# Rust错误处理机制

Rust通过提供强大且灵活的错误处理机制，致力于编写健壮可靠的软件。它将错误分为两大类：**不可恢复的错误**和**可恢复的错误**。本文档将详细探讨这两种错误的处理方式，以及相关的最佳实践。

## 目录

- [错误分类](#错误分类)
- [不可恢复的错误与 `panic!`](#不可恢复的错误与-panic)
- [可恢复的错误与 `Result`](#可恢复的错误与-result)
- [错误传播与 `?` 运算符](#错误传播与--运算符)
- [定义自定义错误类型](#定义自定义错误类型)
- [错误处理库](#错误处理库)
- [实践总结](#实践总结)

## 错误分类

Rust没有像C++或Java那样的异常机制，而是将错误视为程序正常流程的一部分。

- **不可恢复的错误 (Unrecoverable Errors)**: 通常是程序逻辑上的bug，例如数组越界访问。Rust使用 `panic!` 宏来处理这种情况，它会立即中止程序执行。
- **可恢复的错误 (Recoverable Errors)**: 通常是那些可以预料到并且应该被处理的错误，例如文件未找到或网络连接失败。Rust使用 `Result<T, E>` 枚举来处理这类错误。

---

## 不可恢复的错误与 `panic!`

当程序进入一种无法恢复的状态时，`panic!` 是最合适的选择。它表示一个程序员意料之外的严重问题。

### 何时使用 `panic!`

- **示例代码、测试或原型设计**: 在这些场景下，详细的错误处理可能会降低开发速度。
- **违反了代码约定**: 当调用者违反了函数或方法的某种基本约定时（例如，传递了无效的参数），`panic!` 可以明确地指出问题所在。
- **无法处理的外部状态**: 当程序依赖的某个外部状态不满足预期，且无法通过代码逻辑修复时。

### 如何触发 `panic!`

你可以通过调用 `panic!` 宏来主动触发一个panic。

```rust
fn main() {
    // 这将导致程序崩溃并显示错误消息
    panic!("程序崩溃了！这是一个紧急情况！");
}
```

当你运行这段代码时，输出会是：
```text
thread 'main' panicked at '程序崩溃了！这是一个紧急情况！', src/main.rs:2:5
note: run with `RUST_BACKTRACE=1` environment variable to display a backtrace
```

### `panic!` 的回溯信息

默认情况下，`panic!` 会执行**栈展开**（stack unwinding），这意味着Rust会回溯调用栈，并清理每个遇到的函数所拥有的数据。这个过程比较耗时，但能保证资源被正确释放。

你可以通过设置环境变量 `RUST_BACKTRACE=1` 来获取更详细的回溯信息，这对于定位bug非常有帮助。

```bash
$ RUST_BACKTRACE=1 cargo run
```

如果你希望程序在 `panic!` 时立即**中止**（abort），以减小最终二进制文件的大小，你可以在 `Cargo.toml` 中进行配置：
```toml
[profile.release]
panic = 'abort'
```

---

## 可恢复的错误与 `Result`

对于大多数可预见的错误，使用 `Result<T, E>` 枚举是更健壮的方式。

### `Result<T, E>` 枚举

`Result` 枚举定义如下：
```rust
enum Result<T, E> {
    Ok(T),    // 表示操作成功，并包含成功时的值
    Err(E),   // 表示操作失败，并包含失败时的错误信息
}
```

例如，尝试打开一个文件可能会失败，所以 `File::open` 函数返回一个 `Result`：
```rust
use std::fs::File;

fn main() {
    let f = File::open("hello.txt");

    let f = match f {
        Ok(file) => file,
        Err(error) => {
            // 根据不同的错误类型进行处理
            panic!("打开文件失败: {:?}", error);
        }
    };
}
```

### 使用 `match` 匹配不同的错误

`match` 表达式非常适合用来处理 `Result`，你可以根据具体的错误类型（`std::io::ErrorKind`）来采取不同的行动。

```rust
use std::fs::File;
use std::io::ErrorKind;

fn main() {
    let f = File::open("hello.txt");

    let f = match f {
        Ok(file) => file,
        Err(error) => match error.kind() {
            // 如果文件不存在，就创建它
            ErrorKind::NotFound => match File::create("hello.txt") {
                Ok(fc) => fc,
                Err(e) => panic!("创建文件失败: {:?}", e),
            },
            // 其他错误则直接panic
            other_error => {
                panic!("打开文件时遇到问题: {:?}", other_error);
            }
        },
    };
}
```

### 处理 `Result` 的快捷方式

虽然 `match` 很强大，但有时会显得冗长。Rust为此提供了一些便捷的方法。

- **`unwrap()`**: 如果 `Result` 是 `Ok`，`unwrap` 返回其中的值；如果是 `Err`，它会调用 `panic!`。这对于原型开发或你确定操作不会失败的情况很有用。

  ```rust
  let f = File::open("hello.txt").unwrap();
  ```

- **`expect()`**: 与 `unwrap` 类似，但在 `panic!` 时可以提供自定义的错误消息。

  ```rust
  let f = File::open("hello.txt").expect("无法打开文件 hello.txt");
  ```

**警告**: 在生产代码中应谨慎使用 `unwrap` 和 `expect`，因为它们会导致程序崩溃。

---

## 错误传播与 `?` 运算符

当一个函数可能失败时，通常我们希望将错误返回给调用者，而不是在函数内部处理。这个过程称为**错误传播**。

### 手动传播错误

在 `?` 运算符出现之前，错误传播通常通过 `match` 来实现。

```rust
use std::io;
use std::io::Read;
use std::fs::File;

fn read_username_from_file() -> Result<String, io::Error> {
    let f = File::open("hello.txt");

    let mut f = match f {
        Ok(file) => file,
        Err(e) => return Err(e), // 将错误返回
    };

    let mut s = String::new();

    match f.read_to_string(&mut s) {
        Ok(_) => Ok(s),
        Err(e) => Err(e), // 将错误返回
    }
}
```

### 使用 `?` 运算符简化传播

`?` 运算符可以极大地简化错误传播的逻辑。如果 `Result` 的值是 `Ok`，它会从中取出值；如果是 `Err`，`?` 运算符会立即从函数中返回，并将 `Err` 值传递给调用者。

上面的函数可以被重写为：
```rust
use std::io;
use std::io::Read;
use std::fs::File;

fn read_username_from_file() -> Result<String, io::Error> {
    let mut f = File::open("hello.txt")?;
    let mut s = String::new();
    f.read_to_string(&mut s)?;
    Ok(s)
}
```

甚至可以链式调用：
```rust
use std::io;
use std::io::Read;
use std::fs::File;

fn read_username_from_file() -> Result<String, io::Error> {
    let mut s = String::new();
    File::open("hello.txt")?.read_to_string(&mut s)?;
    Ok(s)
}
```
`std::fs::read_to_string` 甚至提供了更简洁的方式，但这展示了 `?` 的强大功能。

**注意**: `?` 运算符只能用于返回类型为 `Result`（或 `Option` 或其他实现了 `Try` 特质的类型）的函数中。

### `?` 与 `main` 函数

`main` 函数也可以返回 `Result`，这使得在程序入口点使用 `?` 运算符成为可能。
```rust
use std::error::Error;
use std::fs::File;

fn main() -> Result<(), Box<dyn Error>> {
    let f = File::open("hello.txt")?;
    Ok(())
}
```
`Box<dyn Error>` 是一个**特质对象**，它代表任何实现了 `Error` 特质的类型。这在处理多种不同错误类型时非常有用。

---

## 定义自定义错误类型

为你的库或应用创建自定义的错误类型是一种良好的实践，它可以提供更具体的错误信息，并使错误处理逻辑更清晰。

一个好的错误类型应该：
- 实现 `std::fmt::Debug` 和 `std::fmt::Display` 特质，以便于调试和用户友好地显示。
- 实现 `std::error::Error` 特质，以便与其他库和工具集成。

```rust
use std::fmt;
use std::error::Error;

// 1. 定义我们的自定义错误类型
#[derive(Debug)]
struct MyError {
    details: String
}

impl MyError {
    fn new(msg: &str) -> MyError {
        MyError{details: msg.to_string()}
    }
}

// 2. 实现 Display，用于用户友好的输出
impl fmt::Display for MyError {
    fn fmt(&self, f: &mut fmt::Formatter) -> fmt::Result {
        write!(f, "{}", self.details)
    }
}

// 3. 实现 Error，用于与其他错误类型交互
impl Error for MyError {
    fn description(&self) -> &str {
        &self.details
    }
}

// 4. 一个返回我们自定义错误类型的函数
fn my_function(n: i32) -> Result<i32, MyError> {
    if n < 0 {
        Err(MyError::new("输入值不能为负数"))
    } else {
        Ok(n * 2)
    }
}

fn main() {
    match my_function(-1) {
        Ok(v) => println!("结果: {}", v),
        Err(e) => println!("错误: {}", e),
    }
}
```

## 错误处理库

虽然标准库提供了强大的基础，但社区也开发了一些优秀的库来进一步简化错误处理。

- **`thiserror`**: 当你为库编写错误类型时，`thiserror` 可以通过派生宏大大减少样板代码。

  ```rust
  // 使用 thiserror
  use thiserror::Error;
  use std::io;

  #[derive(Error, Debug)]
  pub enum DataStoreError {
      #[error("数据未找到")]
      NotFound,
      #[error("IO错误")]
      Io(#[from] io::Error),
      #[error("无效的数据格式: {0}")]
      InvalidFormat(String),
  }
  ```

- **`anyhow`**: 当你编写应用程序（而不是库）时，`anyhow` 提供了一个简单的 `anyhow::Result` 类型，它可以轻松地包装任何实现了 `std::error::Error` 的错误类型，省去了定义多种自定义错误类型的麻烦。

  ```rust
  use anyhow::{Context, Result};

  fn get_data() -> Result<String> {
      let data = std::fs::read_to_string("data.txt")
          .context("无法读取 data.txt 文件")?;
      if data.is_empty() {
          anyhow::bail!("data.txt 文件为空");
      }
      Ok(data)
  }
  ```

## 实践总结

- 对于可能发生的、可预见的错误，**优先使用 `Result<T, E>`**。
- 当遇到程序不应该存在的逻辑错误（bug）时，**使用 `panic!`**。
- 在原型设计和测试中，`unwrap()` 和 `expect()` 是可以接受的，但在生产代码中要避免。
- **使用 `?` 运算符**来传播错误，保持代码简洁。
- 为你的库**定义清晰的自定义错误类型**。
- 在应用程序中，考虑使用 **`anyhow`** 来简化错误处理链。
- 在库中，考虑使用 **`thiserror`** 来减少创建自定义错误类型的样板代码。 